Traceback (most recent call last):
  File "/Users/howie/miniconda3/envs/book/lib/python3.8/site-packages/jupyter_cache/executors/utils.py", line 51, in single_nb_execution
    executenb(
  File "/Users/howie/miniconda3/envs/book/lib/python3.8/site-packages/nbclient/client.py", line 1082, in execute
    return NotebookClient(nb=nb, resources=resources, km=km, **kwargs).execute()
  File "/Users/howie/miniconda3/envs/book/lib/python3.8/site-packages/nbclient/util.py", line 74, in wrapped
    return just_run(coro(*args, **kwargs))
  File "/Users/howie/miniconda3/envs/book/lib/python3.8/site-packages/nbclient/util.py", line 53, in just_run
    return loop.run_until_complete(coro)
  File "/Users/howie/miniconda3/envs/book/lib/python3.8/asyncio/base_events.py", line 616, in run_until_complete
    return future.result()
  File "/Users/howie/miniconda3/envs/book/lib/python3.8/site-packages/nbclient/client.py", line 535, in async_execute
    await self.async_execute_cell(
  File "/Users/howie/miniconda3/envs/book/lib/python3.8/site-packages/nbclient/client.py", line 827, in async_execute_cell
    self._check_raise_for_error(cell, exec_reply)
  File "/Users/howie/miniconda3/envs/book/lib/python3.8/site-packages/nbclient/client.py", line 735, in _check_raise_for_error
    raise CellExecutionError.from_cell_and_msg(cell, exec_reply['content'])
nbclient.exceptions.CellExecutionError: An error occurred while executing the following cell:
------------------
# Ë£ÖÈ•∞Âô®,ÂêÑÁßçÁî®ÈÄî
# author: De8uG


class MyApp():
    def __init__(self):
        self.func_map = {}
 
    def register(self, name):
        def func_wrapper(func):
            print('func_wrapper: ', name, func)
            self.func_map[name] = func
            return func
        return func_wrapper
 
    def call_method(self, name=None):
        func = self.func_map.get(name, None)
        if func is None:
            raise Exception("No function registered against - " + str(name))
        return name, func()


# ÂàõÂª∫ÂØπË±°ÔºåÁî®‰∫éÊ∑ªÂä†ÊñπÊ≥ïËøõË°åË∞ÉÁî®
app = MyApp()

@app.register('/')
def main_page_func():
    return "This is the main page."



def next_page_func():
    return "This is the next page."


print(app.call_method('/'))
print(app.call_method('/next_page'))
------------------

[0;31m---------------------------------------------------------------------------[0m
[0;31mException[0m                                 Traceback (most recent call last)
[0;32m<ipython-input-22-230895b3fdb1>[0m in [0;36m<module>[0;34m[0m
[1;32m     35[0m [0;34m[0m[0m
[1;32m     36[0m [0mprint[0m[0;34m([0m[0mapp[0m[0;34m.[0m[0mcall_method[0m[0;34m([0m[0;34m'/'[0m[0;34m)[0m[0;34m)[0m[0;34m[0m[0;34m[0m[0m
[0;32m---> 37[0;31m [0mprint[0m[0;34m([0m[0mapp[0m[0;34m.[0m[0mcall_method[0m[0;34m([0m[0;34m'/next_page'[0m[0;34m)[0m[0;34m)[0m[0;34m[0m[0;34m[0m[0m
[0m
[0;32m<ipython-input-22-230895b3fdb1>[0m in [0;36mcall_method[0;34m(self, name)[0m
[1;32m     17[0m         [0mfunc[0m [0;34m=[0m [0mself[0m[0;34m.[0m[0mfunc_map[0m[0;34m.[0m[0mget[0m[0;34m([0m[0mname[0m[0;34m,[0m [0;32mNone[0m[0;34m)[0m[0;34m[0m[0;34m[0m[0m
[1;32m     18[0m         [0;32mif[0m [0mfunc[0m [0;32mis[0m [0;32mNone[0m[0;34m:[0m[0;34m[0m[0;34m[0m[0m
[0;32m---> 19[0;31m             [0;32mraise[0m [0mException[0m[0;34m([0m[0;34m"No function registered against - "[0m [0;34m+[0m [0mstr[0m[0;34m([0m[0mname[0m[0;34m)[0m[0;34m)[0m[0;34m[0m[0;34m[0m[0m
[0m[1;32m     20[0m         [0;32mreturn[0m [0mname[0m[0;34m,[0m [0mfunc[0m[0;34m([0m[0;34m)[0m[0;34m[0m[0;34m[0m[0m
[1;32m     21[0m [0;34m[0m[0m

[0;31mException[0m: No function registered against - /next_page
Exception: No function registered against - /next_page

